2018-07-11 17:23:11,405 INFO: Email Robot iniciado [in C:\Users\Charly\python\CFDIsWeb\webapp\__init__.py:33]
2018-07-11 17:29:57,906 INFO: Email Robot iniciado [in C:\Users\Charly\python\CFDIsWeb\webapp\__init__.py:33]
2018-07-11 17:33:34,549 INFO: Email Robot iniciado [in C:\Users\Charly\python\CFDIsWeb\webapp\__init__.py:33]
2018-07-11 17:36:50,084 INFO: Email Robot iniciado [in C:\Users\Charly\python\CFDIsWeb\webapp\__init__.py:33]
2018-07-11 17:47:04,818 INFO: Email Robot iniciado [in C:\Users\Charly\python\CFDIsWeb\webapp\__init__.py:33]
2018-07-12 12:39:32,306 INFO: Email Robot iniciado [in C:\Users\Charly\python\CFDIsWeb\webapp\__init__.py:33]
2018-07-12 12:54:29,536 INFO: Email Robot iniciado [in C:\Users\Charly\python\CFDIsWeb\webapp\__init__.py:33]
2018-07-12 12:54:40,315 ERROR: Exception on / [GET] [in c:\users\charly\python\cfdisweb\venv\lib\site-packages\flask\app.py:1560]
Traceback (most recent call last):
  File "c:\users\charly\python\cfdisweb\venv\lib\site-packages\flask\app.py", line 1982, in wsgi_app
    response = self.full_dispatch_request()
  File "c:\users\charly\python\cfdisweb\venv\lib\site-packages\flask\app.py", line 1614, in full_dispatch_request
    rv = self.handle_user_exception(e)
  File "c:\users\charly\python\cfdisweb\venv\lib\site-packages\flask\app.py", line 1517, in handle_user_exception
    reraise(exc_type, exc_value, tb)
  File "c:\users\charly\python\cfdisweb\venv\lib\site-packages\flask\_compat.py", line 33, in reraise
    raise value
  File "c:\users\charly\python\cfdisweb\venv\lib\site-packages\flask\app.py", line 1612, in full_dispatch_request
    rv = self.dispatch_request()
  File "c:\users\charly\python\cfdisweb\venv\lib\site-packages\flask\app.py", line 1598, in dispatch_request
    return self.view_functions[rule.endpoint](**req.view_args)
  File "c:\users\charly\python\cfdisweb\venv\lib\site-packages\flask_login\utils.py", line 261, in decorated_view
    return func(*args, **kwargs)
  File "C:\Users\Charly\python\CFDIsWeb\webapp\routes.py", line 62, in index
    result = wappdb.execute(s)
AttributeError: 'SQLAlchemy' object has no attribute 'execute'
2018-07-12 12:57:06,510 INFO: Email Robot iniciado [in C:\Users\Charly\python\CFDIsWeb\webapp\__init__.py:33]
2018-07-12 13:01:56,118 INFO: Email Robot iniciado [in C:\Users\Charly\python\CFDIsWeb\webapp\__init__.py:33]
2018-07-12 13:01:58,864 ERROR: Exception on / [GET] [in c:\users\charly\python\cfdisweb\venv\lib\site-packages\flask\app.py:1560]
Traceback (most recent call last):
  File "c:\users\charly\python\cfdisweb\venv\lib\site-packages\flask\app.py", line 1982, in wsgi_app
    response = self.full_dispatch_request()
  File "c:\users\charly\python\cfdisweb\venv\lib\site-packages\flask\app.py", line 1614, in full_dispatch_request
    rv = self.handle_user_exception(e)
  File "c:\users\charly\python\cfdisweb\venv\lib\site-packages\flask\app.py", line 1517, in handle_user_exception
    reraise(exc_type, exc_value, tb)
  File "c:\users\charly\python\cfdisweb\venv\lib\site-packages\flask\_compat.py", line 33, in reraise
    raise value
  File "c:\users\charly\python\cfdisweb\venv\lib\site-packages\flask\app.py", line 1612, in full_dispatch_request
    rv = self.dispatch_request()
  File "c:\users\charly\python\cfdisweb\venv\lib\site-packages\flask\app.py", line 1598, in dispatch_request
    return self.view_functions[rule.endpoint](**req.view_args)
  File "c:\users\charly\python\cfdisweb\venv\lib\site-packages\flask_login\utils.py", line 261, in decorated_view
    return func(*args, **kwargs)
  File "C:\Users\Charly\python\CFDIsWeb\webapp\routes.py", line 62, in index
    result = wappdb.Query.all()
TypeError: all() missing 1 required positional argument: 'self'
2018-07-12 13:02:33,643 INFO: Email Robot iniciado [in C:\Users\Charly\python\CFDIsWeb\webapp\__init__.py:33]
2018-07-12 13:02:36,081 ERROR: Exception on / [GET] [in c:\users\charly\python\cfdisweb\venv\lib\site-packages\flask\app.py:1560]
Traceback (most recent call last):
  File "c:\users\charly\python\cfdisweb\venv\lib\site-packages\flask\app.py", line 1982, in wsgi_app
    response = self.full_dispatch_request()
  File "c:\users\charly\python\cfdisweb\venv\lib\site-packages\flask\app.py", line 1614, in full_dispatch_request
    rv = self.handle_user_exception(e)
  File "c:\users\charly\python\cfdisweb\venv\lib\site-packages\flask\app.py", line 1517, in handle_user_exception
    reraise(exc_type, exc_value, tb)
  File "c:\users\charly\python\cfdisweb\venv\lib\site-packages\flask\_compat.py", line 33, in reraise
    raise value
  File "c:\users\charly\python\cfdisweb\venv\lib\site-packages\flask\app.py", line 1612, in full_dispatch_request
    rv = self.dispatch_request()
  File "c:\users\charly\python\cfdisweb\venv\lib\site-packages\flask\app.py", line 1598, in dispatch_request
    return self.view_functions[rule.endpoint](**req.view_args)
  File "c:\users\charly\python\cfdisweb\venv\lib\site-packages\flask_login\utils.py", line 261, in decorated_view
    return func(*args, **kwargs)
  File "C:\Users\Charly\python\CFDIsWeb\webapp\routes.py", line 62, in index
    result = wappdb.Query.all(CFDI)
  File "c:\users\charly\python\cfdisweb\venv\lib\site-packages\sqlalchemy\orm\query.py", line 2836, in all
    return list(self)
TypeError: 'DefaultMeta' object is not iterable
2018-07-12 13:02:54,515 INFO: Email Robot iniciado [in C:\Users\Charly\python\CFDIsWeb\webapp\__init__.py:33]
2018-07-12 13:02:56,248 ERROR: Exception on / [GET] [in c:\users\charly\python\cfdisweb\venv\lib\site-packages\flask\app.py:1560]
Traceback (most recent call last):
  File "c:\users\charly\python\cfdisweb\venv\lib\site-packages\flask\app.py", line 1982, in wsgi_app
    response = self.full_dispatch_request()
  File "c:\users\charly\python\cfdisweb\venv\lib\site-packages\flask\app.py", line 1614, in full_dispatch_request
    rv = self.handle_user_exception(e)
  File "c:\users\charly\python\cfdisweb\venv\lib\site-packages\flask\app.py", line 1517, in handle_user_exception
    reraise(exc_type, exc_value, tb)
  File "c:\users\charly\python\cfdisweb\venv\lib\site-packages\flask\_compat.py", line 33, in reraise
    raise value
  File "c:\users\charly\python\cfdisweb\venv\lib\site-packages\flask\app.py", line 1612, in full_dispatch_request
    rv = self.dispatch_request()
  File "c:\users\charly\python\cfdisweb\venv\lib\site-packages\flask\app.py", line 1598, in dispatch_request
    return self.view_functions[rule.endpoint](**req.view_args)
  File "c:\users\charly\python\cfdisweb\venv\lib\site-packages\flask_login\utils.py", line 261, in decorated_view
    return func(*args, **kwargs)
  File "C:\Users\Charly\python\CFDIsWeb\webapp\routes.py", line 62, in index
    result = wappdb.Query.all(app)
  File "c:\users\charly\python\cfdisweb\venv\lib\site-packages\sqlalchemy\orm\query.py", line 2836, in all
    return list(self)
TypeError: 'Flask' object is not iterable
2018-07-12 13:03:39,685 INFO: Email Robot iniciado [in C:\Users\Charly\python\CFDIsWeb\webapp\__init__.py:33]
2018-07-12 13:03:40,795 ERROR: Exception on / [GET] [in c:\users\charly\python\cfdisweb\venv\lib\site-packages\flask\app.py:1560]
Traceback (most recent call last):
  File "c:\users\charly\python\cfdisweb\venv\lib\site-packages\flask\app.py", line 1982, in wsgi_app
    response = self.full_dispatch_request()
  File "c:\users\charly\python\cfdisweb\venv\lib\site-packages\flask\app.py", line 1614, in full_dispatch_request
    rv = self.handle_user_exception(e)
  File "c:\users\charly\python\cfdisweb\venv\lib\site-packages\flask\app.py", line 1517, in handle_user_exception
    reraise(exc_type, exc_value, tb)
  File "c:\users\charly\python\cfdisweb\venv\lib\site-packages\flask\_compat.py", line 33, in reraise
    raise value
  File "c:\users\charly\python\cfdisweb\venv\lib\site-packages\flask\app.py", line 1612, in full_dispatch_request
    rv = self.dispatch_request()
  File "c:\users\charly\python\cfdisweb\venv\lib\site-packages\flask\app.py", line 1598, in dispatch_request
    return self.view_functions[rule.endpoint](**req.view_args)
  File "c:\users\charly\python\cfdisweb\venv\lib\site-packages\flask_login\utils.py", line 261, in decorated_view
    return func(*args, **kwargs)
  File "C:\Users\Charly\python\CFDIsWeb\webapp\routes.py", line 62, in index
    result = wappdb.Query.all(CFDI)
  File "c:\users\charly\python\cfdisweb\venv\lib\site-packages\sqlalchemy\orm\query.py", line 2836, in all
    return list(self)
TypeError: 'DefaultMeta' object is not iterable
2018-07-12 13:13:04,287 INFO: Email Robot iniciado [in C:\Users\Charly\python\CFDIsWeb\webapp\__init__.py:33]
