2018-07-11 16:55:07,865 ERROR: Exception on /index [GET] [in c:\users\charly\python\cfdisweb\venv\lib\site-packages\flask\app.py:1560]
Traceback (most recent call last):
  File "c:\users\charly\python\cfdisweb\venv\lib\site-packages\flask\app.py", line 1982, in wsgi_app
    response = self.full_dispatch_request()
  File "c:\users\charly\python\cfdisweb\venv\lib\site-packages\flask\app.py", line 1614, in full_dispatch_request
    rv = self.handle_user_exception(e)
  File "c:\users\charly\python\cfdisweb\venv\lib\site-packages\flask\app.py", line 1517, in handle_user_exception
    reraise(exc_type, exc_value, tb)
  File "c:\users\charly\python\cfdisweb\venv\lib\site-packages\flask\_compat.py", line 33, in reraise
    raise value
  File "c:\users\charly\python\cfdisweb\venv\lib\site-packages\flask\app.py", line 1612, in full_dispatch_request
    rv = self.dispatch_request()
  File "c:\users\charly\python\cfdisweb\venv\lib\site-packages\flask\app.py", line 1598, in dispatch_request
    return self.view_functions[rule.endpoint](**req.view_args)
  File "c:\users\charly\python\cfdisweb\venv\lib\site-packages\flask_login\utils.py", line 261, in decorated_view
    return func(*args, **kwargs)
  File "C:\Users\Charly\python\CFDIsWeb\webapp\routes.py", line 57, in index
    print(cfdi(0))
TypeError: 'CFDI' object is not callable
2018-07-11 16:55:39,278 INFO: Email Robot iniciado [in C:\Users\Charly\python\CFDIsWeb\webapp\__init__.py:33]
2018-07-11 16:55:40,891 ERROR: Exception on /index [GET] [in c:\users\charly\python\cfdisweb\venv\lib\site-packages\flask\app.py:1560]
Traceback (most recent call last):
  File "c:\users\charly\python\cfdisweb\venv\lib\site-packages\flask\app.py", line 1982, in wsgi_app
    response = self.full_dispatch_request()
  File "c:\users\charly\python\cfdisweb\venv\lib\site-packages\flask\app.py", line 1614, in full_dispatch_request
    rv = self.handle_user_exception(e)
  File "c:\users\charly\python\cfdisweb\venv\lib\site-packages\flask\app.py", line 1517, in handle_user_exception
    reraise(exc_type, exc_value, tb)
  File "c:\users\charly\python\cfdisweb\venv\lib\site-packages\flask\_compat.py", line 33, in reraise
    raise value
  File "c:\users\charly\python\cfdisweb\venv\lib\site-packages\flask\app.py", line 1612, in full_dispatch_request
    rv = self.dispatch_request()
  File "c:\users\charly\python\cfdisweb\venv\lib\site-packages\flask\app.py", line 1598, in dispatch_request
    return self.view_functions[rule.endpoint](**req.view_args)
  File "c:\users\charly\python\cfdisweb\venv\lib\site-packages\flask_login\utils.py", line 261, in decorated_view
    return func(*args, **kwargs)
  File "C:\Users\Charly\python\CFDIsWeb\webapp\routes.py", line 57, in index
    print(cfdi[0])
TypeError: 'CFDI' object does not support indexing
2018-07-11 16:56:13,138 INFO: Email Robot iniciado [in C:\Users\Charly\python\CFDIsWeb\webapp\__init__.py:33]
2018-07-11 16:56:17,764 ERROR: Exception on /index [GET] [in c:\users\charly\python\cfdisweb\venv\lib\site-packages\flask\app.py:1560]
Traceback (most recent call last):
  File "c:\users\charly\python\cfdisweb\venv\lib\site-packages\flask\app.py", line 1982, in wsgi_app
    response = self.full_dispatch_request()
  File "c:\users\charly\python\cfdisweb\venv\lib\site-packages\flask\app.py", line 1614, in full_dispatch_request
    rv = self.handle_user_exception(e)
  File "c:\users\charly\python\cfdisweb\venv\lib\site-packages\flask\app.py", line 1517, in handle_user_exception
    reraise(exc_type, exc_value, tb)
  File "c:\users\charly\python\cfdisweb\venv\lib\site-packages\flask\_compat.py", line 33, in reraise
    raise value
  File "c:\users\charly\python\cfdisweb\venv\lib\site-packages\flask\app.py", line 1612, in full_dispatch_request
    rv = self.dispatch_request()
  File "c:\users\charly\python\cfdisweb\venv\lib\site-packages\flask\app.py", line 1598, in dispatch_request
    return self.view_functions[rule.endpoint](**req.view_args)
  File "c:\users\charly\python\cfdisweb\venv\lib\site-packages\flask_login\utils.py", line 261, in decorated_view
    return func(*args, **kwargs)
  File "C:\Users\Charly\python\CFDIsWeb\webapp\routes.py", line 57, in index
    for a in cfdi:
TypeError: 'CFDI' object is not iterable
2018-07-11 16:57:43,422 INFO: Email Robot iniciado [in C:\Users\Charly\python\CFDIsWeb\webapp\__init__.py:33]
2018-07-11 16:57:46,615 ERROR: Exception on /index [GET] [in c:\users\charly\python\cfdisweb\venv\lib\site-packages\flask\app.py:1560]
Traceback (most recent call last):
  File "c:\users\charly\python\cfdisweb\venv\lib\site-packages\flask\app.py", line 1982, in wsgi_app
    response = self.full_dispatch_request()
  File "c:\users\charly\python\cfdisweb\venv\lib\site-packages\flask\app.py", line 1614, in full_dispatch_request
    rv = self.handle_user_exception(e)
  File "c:\users\charly\python\cfdisweb\venv\lib\site-packages\flask\app.py", line 1517, in handle_user_exception
    reraise(exc_type, exc_value, tb)
  File "c:\users\charly\python\cfdisweb\venv\lib\site-packages\flask\_compat.py", line 33, in reraise
    raise value
  File "c:\users\charly\python\cfdisweb\venv\lib\site-packages\flask\app.py", line 1612, in full_dispatch_request
    rv = self.dispatch_request()
  File "c:\users\charly\python\cfdisweb\venv\lib\site-packages\flask\app.py", line 1598, in dispatch_request
    return self.view_functions[rule.endpoint](**req.view_args)
  File "c:\users\charly\python\cfdisweb\venv\lib\site-packages\flask_login\utils.py", line 261, in decorated_view
    return func(*args, **kwargs)
  File "C:\Users\Charly\python\CFDIsWeb\webapp\routes.py", line 56, in index
    c = CFDI.query()
TypeError: 'BaseQuery' object is not callable
2018-07-11 16:58:47,162 INFO: Email Robot iniciado [in C:\Users\Charly\python\CFDIsWeb\webapp\__init__.py:33]
2018-07-11 16:59:30,483 INFO: Email Robot iniciado [in C:\Users\Charly\python\CFDIsWeb\webapp\__init__.py:33]
2018-07-11 16:59:33,989 ERROR: Exception on /index [GET] [in c:\users\charly\python\cfdisweb\venv\lib\site-packages\flask\app.py:1560]
Traceback (most recent call last):
  File "c:\users\charly\python\cfdisweb\venv\lib\site-packages\flask\app.py", line 1982, in wsgi_app
    response = self.full_dispatch_request()
  File "c:\users\charly\python\cfdisweb\venv\lib\site-packages\flask\app.py", line 1614, in full_dispatch_request
    rv = self.handle_user_exception(e)
  File "c:\users\charly\python\cfdisweb\venv\lib\site-packages\flask\app.py", line 1517, in handle_user_exception
    reraise(exc_type, exc_value, tb)
  File "c:\users\charly\python\cfdisweb\venv\lib\site-packages\flask\_compat.py", line 33, in reraise
    raise value
  File "c:\users\charly\python\cfdisweb\venv\lib\site-packages\flask\app.py", line 1612, in full_dispatch_request
    rv = self.dispatch_request()
  File "c:\users\charly\python\cfdisweb\venv\lib\site-packages\flask\app.py", line 1598, in dispatch_request
    return self.view_functions[rule.endpoint](**req.view_args)
  File "c:\users\charly\python\cfdisweb\venv\lib\site-packages\flask_login\utils.py", line 261, in decorated_view
    return func(*args, **kwargs)
  File "C:\Users\Charly\python\CFDIsWeb\webapp\routes.py", line 56, in index
    c = CFDI.query('UUID', 'Version', 'Serie', 'Folio', 'Fecha').filter_by().all()
TypeError: 'BaseQuery' object is not callable
2018-07-11 17:00:48,018 INFO: Email Robot iniciado [in C:\Users\Charly\python\CFDIsWeb\webapp\__init__.py:33]
2018-07-11 17:00:49,753 ERROR: Exception on /index [GET] [in c:\users\charly\python\cfdisweb\venv\lib\site-packages\flask\app.py:1560]
Traceback (most recent call last):
  File "c:\users\charly\python\cfdisweb\venv\lib\site-packages\flask\app.py", line 1982, in wsgi_app
    response = self.full_dispatch_request()
  File "c:\users\charly\python\cfdisweb\venv\lib\site-packages\flask\app.py", line 1614, in full_dispatch_request
    rv = self.handle_user_exception(e)
  File "c:\users\charly\python\cfdisweb\venv\lib\site-packages\flask\app.py", line 1517, in handle_user_exception
    reraise(exc_type, exc_value, tb)
  File "c:\users\charly\python\cfdisweb\venv\lib\site-packages\flask\_compat.py", line 33, in reraise
    raise value
  File "c:\users\charly\python\cfdisweb\venv\lib\site-packages\flask\app.py", line 1612, in full_dispatch_request
    rv = self.dispatch_request()
  File "c:\users\charly\python\cfdisweb\venv\lib\site-packages\flask\app.py", line 1598, in dispatch_request
    return self.view_functions[rule.endpoint](**req.view_args)
  File "c:\users\charly\python\cfdisweb\venv\lib\site-packages\flask_login\utils.py", line 261, in decorated_view
    return func(*args, **kwargs)
  File "C:\Users\Charly\python\CFDIsWeb\webapp\routes.py", line 56, in index
    c = CFDI.query(UUID, version, serie, folio, fecha).filter_by().all()
NameError: name 'UUID' is not defined
2018-07-11 17:01:20,966 INFO: Email Robot iniciado [in C:\Users\Charly\python\CFDIsWeb\webapp\__init__.py:33]
