2018-07-11 17:01:23,363 ERROR: Exception on /index [GET] [in c:\users\charly\python\cfdisweb\venv\lib\site-packages\flask\app.py:1560]
Traceback (most recent call last):
  File "c:\users\charly\python\cfdisweb\venv\lib\site-packages\flask\app.py", line 1982, in wsgi_app
    response = self.full_dispatch_request()
  File "c:\users\charly\python\cfdisweb\venv\lib\site-packages\flask\app.py", line 1614, in full_dispatch_request
    rv = self.handle_user_exception(e)
  File "c:\users\charly\python\cfdisweb\venv\lib\site-packages\flask\app.py", line 1517, in handle_user_exception
    reraise(exc_type, exc_value, tb)
  File "c:\users\charly\python\cfdisweb\venv\lib\site-packages\flask\_compat.py", line 33, in reraise
    raise value
  File "c:\users\charly\python\cfdisweb\venv\lib\site-packages\flask\app.py", line 1612, in full_dispatch_request
    rv = self.dispatch_request()
  File "c:\users\charly\python\cfdisweb\venv\lib\site-packages\flask\app.py", line 1598, in dispatch_request
    return self.view_functions[rule.endpoint](**req.view_args)
  File "c:\users\charly\python\cfdisweb\venv\lib\site-packages\flask_login\utils.py", line 261, in decorated_view
    return func(*args, **kwargs)
  File "C:\Users\Charly\python\CFDIsWeb\webapp\routes.py", line 56, in index
    c = CFDI.query().all()
TypeError: 'BaseQuery' object is not callable
2018-07-11 17:01:33,795 INFO: Email Robot iniciado [in C:\Users\Charly\python\CFDIsWeb\webapp\__init__.py:33]
2018-07-11 17:01:35,181 ERROR: Exception on /index [GET] [in c:\users\charly\python\cfdisweb\venv\lib\site-packages\flask\app.py:1560]
Traceback (most recent call last):
  File "c:\users\charly\python\cfdisweb\venv\lib\site-packages\flask\app.py", line 1982, in wsgi_app
    response = self.full_dispatch_request()
  File "c:\users\charly\python\cfdisweb\venv\lib\site-packages\flask\app.py", line 1614, in full_dispatch_request
    rv = self.handle_user_exception(e)
  File "c:\users\charly\python\cfdisweb\venv\lib\site-packages\flask\app.py", line 1517, in handle_user_exception
    reraise(exc_type, exc_value, tb)
  File "c:\users\charly\python\cfdisweb\venv\lib\site-packages\flask\_compat.py", line 33, in reraise
    raise value
  File "c:\users\charly\python\cfdisweb\venv\lib\site-packages\flask\app.py", line 1612, in full_dispatch_request
    rv = self.dispatch_request()
  File "c:\users\charly\python\cfdisweb\venv\lib\site-packages\flask\app.py", line 1598, in dispatch_request
    return self.view_functions[rule.endpoint](**req.view_args)
  File "c:\users\charly\python\cfdisweb\venv\lib\site-packages\flask_login\utils.py", line 261, in decorated_view
    return func(*args, **kwargs)
  File "C:\Users\Charly\python\CFDIsWeb\webapp\routes.py", line 56, in index
    c = CFDI.query().filter_by().all()
TypeError: 'BaseQuery' object is not callable
2018-07-11 17:01:38,023 ERROR: Exception on /index [GET] [in c:\users\charly\python\cfdisweb\venv\lib\site-packages\flask\app.py:1560]
Traceback (most recent call last):
  File "c:\users\charly\python\cfdisweb\venv\lib\site-packages\flask\app.py", line 1982, in wsgi_app
    response = self.full_dispatch_request()
  File "c:\users\charly\python\cfdisweb\venv\lib\site-packages\flask\app.py", line 1614, in full_dispatch_request
    rv = self.handle_user_exception(e)
  File "c:\users\charly\python\cfdisweb\venv\lib\site-packages\flask\app.py", line 1517, in handle_user_exception
    reraise(exc_type, exc_value, tb)
  File "c:\users\charly\python\cfdisweb\venv\lib\site-packages\flask\_compat.py", line 33, in reraise
    raise value
  File "c:\users\charly\python\cfdisweb\venv\lib\site-packages\flask\app.py", line 1612, in full_dispatch_request
    rv = self.dispatch_request()
  File "c:\users\charly\python\cfdisweb\venv\lib\site-packages\flask\app.py", line 1598, in dispatch_request
    return self.view_functions[rule.endpoint](**req.view_args)
  File "c:\users\charly\python\cfdisweb\venv\lib\site-packages\flask_login\utils.py", line 261, in decorated_view
    return func(*args, **kwargs)
  File "C:\Users\Charly\python\CFDIsWeb\webapp\routes.py", line 56, in index
    c = CFDI.query().filter_by().all()
TypeError: 'BaseQuery' object is not callable
2018-07-11 17:02:38,735 INFO: Email Robot iniciado [in C:\Users\Charly\python\CFDIsWeb\webapp\__init__.py:33]
2018-07-11 17:03:06,871 INFO: Email Robot iniciado [in C:\Users\Charly\python\CFDIsWeb\webapp\__init__.py:33]
2018-07-11 17:03:36,938 INFO: Email Robot iniciado [in C:\Users\Charly\python\CFDIsWeb\webapp\__init__.py:33]
2018-07-11 17:04:07,154 INFO: Email Robot iniciado [in C:\Users\Charly\python\CFDIsWeb\webapp\__init__.py:33]
2018-07-11 17:08:07,307 INFO: Email Robot iniciado [in C:\Users\Charly\python\CFDIsWeb\webapp\__init__.py:33]
2018-07-11 17:08:12,587 ERROR: Exception on /index [GET] [in c:\users\charly\python\cfdisweb\venv\lib\site-packages\flask\app.py:1560]
Traceback (most recent call last):
  File "c:\users\charly\python\cfdisweb\venv\lib\site-packages\flask\app.py", line 1982, in wsgi_app
    response = self.full_dispatch_request()
  File "c:\users\charly\python\cfdisweb\venv\lib\site-packages\flask\app.py", line 1614, in full_dispatch_request
    rv = self.handle_user_exception(e)
  File "c:\users\charly\python\cfdisweb\venv\lib\site-packages\flask\app.py", line 1517, in handle_user_exception
    reraise(exc_type, exc_value, tb)
  File "c:\users\charly\python\cfdisweb\venv\lib\site-packages\flask\_compat.py", line 33, in reraise
    raise value
  File "c:\users\charly\python\cfdisweb\venv\lib\site-packages\flask\app.py", line 1612, in full_dispatch_request
    rv = self.dispatch_request()
  File "c:\users\charly\python\cfdisweb\venv\lib\site-packages\flask\app.py", line 1598, in dispatch_request
    return self.view_functions[rule.endpoint](**req.view_args)
  File "c:\users\charly\python\cfdisweb\venv\lib\site-packages\flask_login\utils.py", line 261, in decorated_view
    return func(*args, **kwargs)
  File "C:\Users\Charly\python\CFDIsWeb\webapp\routes.py", line 60, in index
    l.append((line.UUID, line.version, line.serie, line.folio, line.fecha))
AttributeError: 'CFDI' object has no attribute 'UUID'
2018-07-11 17:08:59,972 INFO: Email Robot iniciado [in C:\Users\Charly\python\CFDIsWeb\webapp\__init__.py:33]
2018-07-11 17:11:21,235 INFO: Email Robot iniciado [in C:\Users\Charly\python\CFDIsWeb\webapp\__init__.py:33]
2018-07-11 17:11:23,047 ERROR: Exception on /index [GET] [in c:\users\charly\python\cfdisweb\venv\lib\site-packages\flask\app.py:1560]
Traceback (most recent call last):
  File "c:\users\charly\python\cfdisweb\venv\lib\site-packages\flask\app.py", line 1982, in wsgi_app
    response = self.full_dispatch_request()
  File "c:\users\charly\python\cfdisweb\venv\lib\site-packages\flask\app.py", line 1614, in full_dispatch_request
    rv = self.handle_user_exception(e)
  File "c:\users\charly\python\cfdisweb\venv\lib\site-packages\flask\app.py", line 1517, in handle_user_exception
    reraise(exc_type, exc_value, tb)
  File "c:\users\charly\python\cfdisweb\venv\lib\site-packages\flask\_compat.py", line 33, in reraise
    raise value
  File "c:\users\charly\python\cfdisweb\venv\lib\site-packages\flask\app.py", line 1612, in full_dispatch_request
    rv = self.dispatch_request()
  File "c:\users\charly\python\cfdisweb\venv\lib\site-packages\flask\app.py", line 1598, in dispatch_request
    return self.view_functions[rule.endpoint](**req.view_args)
  File "c:\users\charly\python\cfdisweb\venv\lib\site-packages\flask_login\utils.py", line 261, in decorated_view
    return func(*args, **kwargs)
  File "C:\Users\Charly\python\CFDIsWeb\webapp\routes.py", line 61, in index
    return render_template('index.html', title='Inicio', columnas=cols, facturas=facts)
  File "c:\users\charly\python\cfdisweb\venv\lib\site-packages\flask\templating.py", line 134, in render_template
    context, ctx.app)
  File "c:\users\charly\python\cfdisweb\venv\lib\site-packages\flask\templating.py", line 116, in _render
    rv = template.render(context)
  File "c:\users\charly\python\cfdisweb\venv\lib\site-packages\jinja2\asyncsupport.py", line 76, in render
    return original_render(self, *args, **kwargs)
  File "c:\users\charly\python\cfdisweb\venv\lib\site-packages\jinja2\environment.py", line 1008, in render
    return self.environment.handle_exception(exc_info, True)
  File "c:\users\charly\python\cfdisweb\venv\lib\site-packages\jinja2\environment.py", line 780, in handle_exception
    reraise(exc_type, exc_value, tb)
  File "c:\users\charly\python\cfdisweb\venv\lib\site-packages\jinja2\_compat.py", line 37, in reraise
    raise value.with_traceback(tb)
  File "C:\Users\Charly\python\CFDIsWeb\webapp\templates\index.html", line 2, in top-level template code
    {% import 'bootstrap/wtf.html' as wtf %}
  File "C:\Users\Charly\python\CFDIsWeb\webapp\templates\base.html", line 1, in top-level template code
    {% extends 'bootstrap/base.html' %}
  File "c:\users\charly\python\cfdisweb\venv\lib\site-packages\flask_bootstrap\templates\bootstrap\base.html", line 1, in top-level template code
    {% block doc -%}
  File "c:\users\charly\python\cfdisweb\venv\lib\site-packages\flask_bootstrap\templates\bootstrap\base.html", line 4, in block "doc"
    {%- block html %}
  File "c:\users\charly\python\cfdisweb\venv\lib\site-packages\flask_bootstrap\templates\bootstrap\base.html", line 20, in block "html"
    {% block body -%}
  File "c:\users\charly\python\cfdisweb\venv\lib\site-packages\flask_bootstrap\templates\bootstrap\base.html", line 23, in block "body"
    {% block content -%}
  File "C:\Users\Charly\python\CFDIsWeb\webapp\templates\base.html", line 58, in block "content"
    {% block app_content %}{% endblock %}
  File "C:\Users\Charly\python\CFDIsWeb\webapp\templates\index.html", line 18, in block "app_content"
    <td>{{f(0)}}</td>
TypeError: 'tuple' object is not callable
2018-07-11 17:13:05,896 INFO: Email Robot iniciado [in C:\Users\Charly\python\CFDIsWeb\webapp\__init__.py:33]
2018-07-11 17:19:58,445 INFO: Email Robot iniciado [in C:\Users\Charly\python\CFDIsWeb\webapp\__init__.py:33]
